{
 "cells": [
  {
   "cell_type": "code",
   "execution_count": 1,
   "metadata": {},
   "outputs": [],
   "source": [
    "import random\n",
    "import numpy as np\n",
    "from environment import Env\n",
    "import tensorflow as tf\n",
    "from tensorflow.keras.layers import Dense"
   ]
  },
  {
   "cell_type": "code",
   "execution_count": 2,
   "metadata": {},
   "outputs": [],
   "source": [
    "# 딥살사 인공신경망\n",
    "class DeepSARSA(tf.keras.Model):\n",
    "    def __init__(self, action_size):\n",
    "        super(DeepSARSA, self).__init__()\n",
    "        self.fc1 = Dense(30, activation='relu')\n",
    "        self.fc2 = Dense(30, activation='relu')\n",
    "        self.fc_out = Dense(action_size, activation='linear')\n",
    "\n",
    "    def call(self, x):\n",
    "        x = self.fc1(x)\n",
    "        x = self.fc2(x)\n",
    "        q = self.fc_out(x)\n",
    "        return q"
   ]
  },
  {
   "cell_type": "code",
   "execution_count": 3,
   "metadata": {},
   "outputs": [],
   "source": [
    "# Deep_sarsa Agent at Grid world\n",
    "\n",
    "class DeepSARSAgent:\n",
    "    def __init(self, state_size, action_size):\n",
    "        self.state_size = state_size\n",
    "        self.action_size = action_size\n",
    "        \n",
    "        self.epsilon = 0.01\n",
    "        self.model = DeepSARSA(self.action_size)\n",
    "        self.model.load_weights('./save_model/deep_sarsa.h5')\n",
    "        \n",
    "    def get_action(self, state):\n",
    "        if no.random.rand() <= self.epsilon:\n",
    "            return random.randrange(self.action_size)\n",
    "        else:\n",
    "            q_values = self.model.predict(state)\n",
    "            return np.argmax(q_values[0])"
   ]
  },
  {
   "cell_type": "code",
   "execution_count": null,
   "metadata": {},
   "outputs": [
    {
     "name": "stderr",
     "output_type": "stream",
     "text": [
      "ERROR:root:Internal Python error in the inspect module.\n",
      "Below is the traceback from this internal error.\n",
      "\n",
      "ERROR:root:Internal Python error in the inspect module.\n",
      "Below is the traceback from this internal error.\n",
      "\n",
      "ERROR:root:Internal Python error in the inspect module.\n",
      "Below is the traceback from this internal error.\n",
      "\n"
     ]
    },
    {
     "name": "stdout",
     "output_type": "stream",
     "text": [
      "Traceback (most recent call last):\n",
      "  File \"/home/soohyoen/anaconda3/envs/rein_study/lib/python3.7/site-packages/IPython/core/interactiveshell.py\", line 3457, in run_code\n",
      "    exec(code_obj, self.user_global_ns, self.user_ns)\n",
      "  File \"/tmp/ipykernel_14187/2142185451.py\", line 4, in <module>\n",
      "    env = Env(render_speed=0.05)\n",
      "TypeError: __init__() got an unexpected keyword argument 'render_speed'\n",
      "\n",
      "During handling of the above exception, another exception occurred:\n",
      "\n",
      "Traceback (most recent call last):\n",
      "  File \"/home/soohyoen/anaconda3/envs/rein_study/lib/python3.7/site-packages/IPython/core/interactiveshell.py\", line 2077, in showtraceback\n",
      "    stb = value._render_traceback_()\n",
      "AttributeError: 'TypeError' object has no attribute '_render_traceback_'\n",
      "\n",
      "During handling of the above exception, another exception occurred:\n",
      "\n",
      "Traceback (most recent call last):\n",
      "  File \"/home/soohyoen/anaconda3/envs/rein_study/lib/python3.7/site-packages/IPython/core/ultratb.py\", line 1101, in get_records\n",
      "    return _fixed_getinnerframes(etb, number_of_lines_of_context, tb_offset)\n",
      "  File \"/home/soohyoen/anaconda3/envs/rein_study/lib/python3.7/site-packages/IPython/core/ultratb.py\", line 248, in wrapped\n",
      "    return f(*args, **kwargs)\n",
      "  File \"/home/soohyoen/anaconda3/envs/rein_study/lib/python3.7/site-packages/IPython/core/ultratb.py\", line 281, in _fixed_getinnerframes\n",
      "    records = fix_frame_records_filenames(inspect.getinnerframes(etb, context))\n",
      "  File \"/home/soohyoen/anaconda3/envs/rein_study/lib/python3.7/inspect.py\", line 1502, in getinnerframes\n",
      "    frameinfo = (tb.tb_frame,) + getframeinfo(tb, context)\n",
      "  File \"/home/soohyoen/anaconda3/envs/rein_study/lib/python3.7/inspect.py\", line 1460, in getframeinfo\n",
      "    filename = getsourcefile(frame) or getfile(frame)\n",
      "  File \"/home/soohyoen/anaconda3/envs/rein_study/lib/python3.7/inspect.py\", line 696, in getsourcefile\n",
      "    if getattr(getmodule(object, filename), '__loader__', None) is not None:\n",
      "  File \"/home/soohyoen/anaconda3/envs/rein_study/lib/python3.7/inspect.py\", line 733, in getmodule\n",
      "    if ismodule(module) and hasattr(module, '__file__'):\n",
      "  File \"/home/soohyoen/anaconda3/envs/rein_study/lib/python3.7/site-packages/tensorflow/__init__.py\", line 50, in __getattr__\n",
      "    module = self._load()\n",
      "  File \"/home/soohyoen/anaconda3/envs/rein_study/lib/python3.7/site-packages/tensorflow/__init__.py\", line 44, in _load\n",
      "    module = _importlib.import_module(self.__name__)\n",
      "  File \"/home/soohyoen/anaconda3/envs/rein_study/lib/python3.7/importlib/__init__.py\", line 127, in import_module\n",
      "    return _bootstrap._gcd_import(name[level:], package, level)\n",
      "  File \"<frozen importlib._bootstrap>\", line 1006, in _gcd_import\n",
      "  File \"<frozen importlib._bootstrap>\", line 983, in _find_and_load\n",
      "  File \"<frozen importlib._bootstrap>\", line 965, in _find_and_load_unlocked\n",
      "ModuleNotFoundError: No module named 'tensorflow_core.estimator'\n",
      "Traceback (most recent call last):\n",
      "  File \"/home/soohyoen/anaconda3/envs/rein_study/lib/python3.7/site-packages/IPython/core/interactiveshell.py\", line 3457, in run_code\n",
      "    exec(code_obj, self.user_global_ns, self.user_ns)\n",
      "  File \"/tmp/ipykernel_14187/2142185451.py\", line 4, in <module>\n",
      "    env = Env(render_speed=0.05)\n",
      "TypeError: __init__() got an unexpected keyword argument 'render_speed'\n",
      "\n",
      "During handling of the above exception, another exception occurred:\n",
      "\n",
      "Traceback (most recent call last):\n",
      "  File \"/home/soohyoen/anaconda3/envs/rein_study/lib/python3.7/site-packages/IPython/core/interactiveshell.py\", line 2077, in showtraceback\n",
      "    stb = value._render_traceback_()\n",
      "AttributeError: 'TypeError' object has no attribute '_render_traceback_'\n",
      "\n",
      "During handling of the above exception, another exception occurred:\n",
      "\n",
      "Traceback (most recent call last):\n",
      "  File \"/home/soohyoen/anaconda3/envs/rein_study/lib/python3.7/site-packages/IPython/core/interactiveshell.py\", line 3377, in run_ast_nodes\n",
      "    if (await self.run_code(code, result,  async_=asy)):\n",
      "  File \"/home/soohyoen/anaconda3/envs/rein_study/lib/python3.7/site-packages/IPython/core/interactiveshell.py\", line 3474, in run_code\n",
      "    self.showtraceback(running_compiled_code=True)\n",
      "  File \"/home/soohyoen/anaconda3/envs/rein_study/lib/python3.7/site-packages/IPython/core/interactiveshell.py\", line 2080, in showtraceback\n",
      "    value, tb, tb_offset=tb_offset)\n",
      "  File \"/home/soohyoen/anaconda3/envs/rein_study/lib/python3.7/site-packages/IPython/core/ultratb.py\", line 1368, in structured_traceback\n",
      "    self, etype, value, tb, tb_offset, number_of_lines_of_context)\n",
      "  File \"/home/soohyoen/anaconda3/envs/rein_study/lib/python3.7/site-packages/IPython/core/ultratb.py\", line 1268, in structured_traceback\n",
      "    self, etype, value, tb, tb_offset, number_of_lines_of_context\n",
      "  File \"/home/soohyoen/anaconda3/envs/rein_study/lib/python3.7/site-packages/IPython/core/ultratb.py\", line 1125, in structured_traceback\n",
      "    tb_offset)\n",
      "  File \"/home/soohyoen/anaconda3/envs/rein_study/lib/python3.7/site-packages/IPython/core/ultratb.py\", line 1082, in format_exception_as_a_whole\n",
      "    last_unique, recursion_repeat = find_recursion(orig_etype, evalue, records)\n",
      "  File \"/home/soohyoen/anaconda3/envs/rein_study/lib/python3.7/site-packages/IPython/core/ultratb.py\", line 382, in find_recursion\n",
      "    return len(records), 0\n",
      "TypeError: object of type 'NoneType' has no len()\n",
      "\n",
      "During handling of the above exception, another exception occurred:\n",
      "\n",
      "Traceback (most recent call last):\n",
      "  File \"/home/soohyoen/anaconda3/envs/rein_study/lib/python3.7/site-packages/IPython/core/interactiveshell.py\", line 2077, in showtraceback\n",
      "    stb = value._render_traceback_()\n",
      "AttributeError: 'TypeError' object has no attribute '_render_traceback_'\n",
      "\n",
      "During handling of the above exception, another exception occurred:\n",
      "\n",
      "Traceback (most recent call last):\n",
      "  File \"/home/soohyoen/anaconda3/envs/rein_study/lib/python3.7/site-packages/IPython/core/ultratb.py\", line 1101, in get_records\n",
      "    return _fixed_getinnerframes(etb, number_of_lines_of_context, tb_offset)\n",
      "  File \"/home/soohyoen/anaconda3/envs/rein_study/lib/python3.7/site-packages/IPython/core/ultratb.py\", line 248, in wrapped\n",
      "    return f(*args, **kwargs)\n",
      "  File \"/home/soohyoen/anaconda3/envs/rein_study/lib/python3.7/site-packages/IPython/core/ultratb.py\", line 281, in _fixed_getinnerframes\n",
      "    records = fix_frame_records_filenames(inspect.getinnerframes(etb, context))\n",
      "  File \"/home/soohyoen/anaconda3/envs/rein_study/lib/python3.7/inspect.py\", line 1502, in getinnerframes\n",
      "    frameinfo = (tb.tb_frame,) + getframeinfo(tb, context)\n",
      "  File \"/home/soohyoen/anaconda3/envs/rein_study/lib/python3.7/inspect.py\", line 1460, in getframeinfo\n",
      "    filename = getsourcefile(frame) or getfile(frame)\n",
      "  File \"/home/soohyoen/anaconda3/envs/rein_study/lib/python3.7/inspect.py\", line 696, in getsourcefile\n",
      "    if getattr(getmodule(object, filename), '__loader__', None) is not None:\n",
      "  File \"/home/soohyoen/anaconda3/envs/rein_study/lib/python3.7/inspect.py\", line 733, in getmodule\n",
      "    if ismodule(module) and hasattr(module, '__file__'):\n",
      "  File \"/home/soohyoen/anaconda3/envs/rein_study/lib/python3.7/site-packages/tensorflow/__init__.py\", line 50, in __getattr__\n",
      "    module = self._load()\n",
      "  File \"/home/soohyoen/anaconda3/envs/rein_study/lib/python3.7/site-packages/tensorflow/__init__.py\", line 44, in _load\n",
      "    module = _importlib.import_module(self.__name__)\n",
      "  File \"/home/soohyoen/anaconda3/envs/rein_study/lib/python3.7/importlib/__init__.py\", line 127, in import_module\n",
      "    return _bootstrap._gcd_import(name[level:], package, level)\n",
      "  File \"<frozen importlib._bootstrap>\", line 1006, in _gcd_import\n",
      "  File \"<frozen importlib._bootstrap>\", line 983, in _find_and_load\n",
      "  File \"<frozen importlib._bootstrap>\", line 965, in _find_and_load_unlocked\n",
      "ModuleNotFoundError: No module named 'tensorflow_core.estimator'\n",
      "Traceback (most recent call last):\n",
      "  File \"/home/soohyoen/anaconda3/envs/rein_study/lib/python3.7/site-packages/IPython/core/interactiveshell.py\", line 3457, in run_code\n",
      "    exec(code_obj, self.user_global_ns, self.user_ns)\n",
      "  File \"/tmp/ipykernel_14187/2142185451.py\", line 4, in <module>\n",
      "    env = Env(render_speed=0.05)\n",
      "TypeError: __init__() got an unexpected keyword argument 'render_speed'\n",
      "\n",
      "During handling of the above exception, another exception occurred:\n",
      "\n",
      "Traceback (most recent call last):\n",
      "  File \"/home/soohyoen/anaconda3/envs/rein_study/lib/python3.7/site-packages/IPython/core/interactiveshell.py\", line 2077, in showtraceback\n",
      "    stb = value._render_traceback_()\n",
      "AttributeError: 'TypeError' object has no attribute '_render_traceback_'\n",
      "\n",
      "During handling of the above exception, another exception occurred:\n",
      "\n",
      "Traceback (most recent call last):\n",
      "  File \"/home/soohyoen/anaconda3/envs/rein_study/lib/python3.7/site-packages/IPython/core/interactiveshell.py\", line 3377, in run_ast_nodes\n",
      "    if (await self.run_code(code, result,  async_=asy)):\n",
      "  File \"/home/soohyoen/anaconda3/envs/rein_study/lib/python3.7/site-packages/IPython/core/interactiveshell.py\", line 3474, in run_code\n",
      "    self.showtraceback(running_compiled_code=True)\n",
      "  File \"/home/soohyoen/anaconda3/envs/rein_study/lib/python3.7/site-packages/IPython/core/interactiveshell.py\", line 2080, in showtraceback\n",
      "    value, tb, tb_offset=tb_offset)\n",
      "  File \"/home/soohyoen/anaconda3/envs/rein_study/lib/python3.7/site-packages/IPython/core/ultratb.py\", line 1368, in structured_traceback\n",
      "    self, etype, value, tb, tb_offset, number_of_lines_of_context)\n",
      "  File \"/home/soohyoen/anaconda3/envs/rein_study/lib/python3.7/site-packages/IPython/core/ultratb.py\", line 1268, in structured_traceback\n",
      "    self, etype, value, tb, tb_offset, number_of_lines_of_context\n",
      "  File \"/home/soohyoen/anaconda3/envs/rein_study/lib/python3.7/site-packages/IPython/core/ultratb.py\", line 1125, in structured_traceback\n",
      "    tb_offset)\n",
      "  File \"/home/soohyoen/anaconda3/envs/rein_study/lib/python3.7/site-packages/IPython/core/ultratb.py\", line 1082, in format_exception_as_a_whole\n",
      "    last_unique, recursion_repeat = find_recursion(orig_etype, evalue, records)\n",
      "  File \"/home/soohyoen/anaconda3/envs/rein_study/lib/python3.7/site-packages/IPython/core/ultratb.py\", line 382, in find_recursion\n",
      "    return len(records), 0\n",
      "TypeError: object of type 'NoneType' has no len()\n",
      "\n",
      "During handling of the above exception, another exception occurred:\n",
      "\n",
      "Traceback (most recent call last):\n",
      "  File \"/home/soohyoen/anaconda3/envs/rein_study/lib/python3.7/site-packages/IPython/core/interactiveshell.py\", line 2077, in showtraceback\n",
      "    stb = value._render_traceback_()\n",
      "AttributeError: 'TypeError' object has no attribute '_render_traceback_'\n",
      "\n",
      "During handling of the above exception, another exception occurred:\n",
      "\n",
      "Traceback (most recent call last):\n",
      "  File \"/home/soohyoen/anaconda3/envs/rein_study/lib/python3.7/site-packages/IPython/core/interactiveshell.py\", line 2960, in _run_cell\n",
      "    return runner(coro)\n",
      "  File \"/home/soohyoen/anaconda3/envs/rein_study/lib/python3.7/site-packages/IPython/core/async_helpers.py\", line 78, in _pseudo_sync_runner\n",
      "    coro.send(None)\n",
      "  File \"/home/soohyoen/anaconda3/envs/rein_study/lib/python3.7/site-packages/IPython/core/interactiveshell.py\", line 3186, in run_cell_async\n",
      "    interactivity=interactivity, compiler=compiler, result=result)\n",
      "  File \"/home/soohyoen/anaconda3/envs/rein_study/lib/python3.7/site-packages/IPython/core/interactiveshell.py\", line 3396, in run_ast_nodes\n",
      "    self.showtraceback()\n",
      "  File \"/home/soohyoen/anaconda3/envs/rein_study/lib/python3.7/site-packages/IPython/core/interactiveshell.py\", line 2080, in showtraceback\n",
      "    value, tb, tb_offset=tb_offset)\n",
      "  File \"/home/soohyoen/anaconda3/envs/rein_study/lib/python3.7/site-packages/IPython/core/ultratb.py\", line 1368, in structured_traceback\n",
      "    self, etype, value, tb, tb_offset, number_of_lines_of_context)\n",
      "  File \"/home/soohyoen/anaconda3/envs/rein_study/lib/python3.7/site-packages/IPython/core/ultratb.py\", line 1268, in structured_traceback\n",
      "    self, etype, value, tb, tb_offset, number_of_lines_of_context\n",
      "  File \"/home/soohyoen/anaconda3/envs/rein_study/lib/python3.7/site-packages/IPython/core/ultratb.py\", line 1143, in structured_traceback\n",
      "    chained_exceptions_tb_offset)\n",
      "  File \"/home/soohyoen/anaconda3/envs/rein_study/lib/python3.7/site-packages/IPython/core/ultratb.py\", line 1082, in format_exception_as_a_whole\n",
      "    last_unique, recursion_repeat = find_recursion(orig_etype, evalue, records)\n",
      "  File \"/home/soohyoen/anaconda3/envs/rein_study/lib/python3.7/site-packages/IPython/core/ultratb.py\", line 382, in find_recursion\n",
      "    return len(records), 0\n",
      "TypeError: object of type 'NoneType' has no len()\n",
      "\n",
      "During handling of the above exception, another exception occurred:\n",
      "\n",
      "Traceback (most recent call last):\n",
      "  File \"/home/soohyoen/anaconda3/envs/rein_study/lib/python3.7/site-packages/IPython/core/interactiveshell.py\", line 2077, in showtraceback\n",
      "    stb = value._render_traceback_()\n",
      "AttributeError: 'TypeError' object has no attribute '_render_traceback_'\n",
      "\n",
      "During handling of the above exception, another exception occurred:\n",
      "\n",
      "Traceback (most recent call last):\n",
      "  File \"/home/soohyoen/anaconda3/envs/rein_study/lib/python3.7/site-packages/IPython/core/ultratb.py\", line 1101, in get_records\n",
      "    return _fixed_getinnerframes(etb, number_of_lines_of_context, tb_offset)\n",
      "  File \"/home/soohyoen/anaconda3/envs/rein_study/lib/python3.7/site-packages/IPython/core/ultratb.py\", line 248, in wrapped\n",
      "    return f(*args, **kwargs)\n",
      "  File \"/home/soohyoen/anaconda3/envs/rein_study/lib/python3.7/site-packages/IPython/core/ultratb.py\", line 281, in _fixed_getinnerframes\n",
      "    records = fix_frame_records_filenames(inspect.getinnerframes(etb, context))\n",
      "  File \"/home/soohyoen/anaconda3/envs/rein_study/lib/python3.7/inspect.py\", line 1502, in getinnerframes\n",
      "    frameinfo = (tb.tb_frame,) + getframeinfo(tb, context)\n",
      "  File \"/home/soohyoen/anaconda3/envs/rein_study/lib/python3.7/inspect.py\", line 1460, in getframeinfo\n",
      "    filename = getsourcefile(frame) or getfile(frame)\n",
      "  File \"/home/soohyoen/anaconda3/envs/rein_study/lib/python3.7/inspect.py\", line 696, in getsourcefile\n",
      "    if getattr(getmodule(object, filename), '__loader__', None) is not None:\n",
      "  File \"/home/soohyoen/anaconda3/envs/rein_study/lib/python3.7/inspect.py\", line 733, in getmodule\n",
      "    if ismodule(module) and hasattr(module, '__file__'):\n",
      "  File \"/home/soohyoen/anaconda3/envs/rein_study/lib/python3.7/site-packages/tensorflow/__init__.py\", line 50, in __getattr__\n",
      "    module = self._load()\n",
      "  File \"/home/soohyoen/anaconda3/envs/rein_study/lib/python3.7/site-packages/tensorflow/__init__.py\", line 44, in _load\n",
      "    module = _importlib.import_module(self.__name__)\n",
      "  File \"/home/soohyoen/anaconda3/envs/rein_study/lib/python3.7/importlib/__init__.py\", line 127, in import_module\n",
      "    return _bootstrap._gcd_import(name[level:], package, level)\n",
      "  File \"<frozen importlib._bootstrap>\", line 1006, in _gcd_import\n",
      "  File \"<frozen importlib._bootstrap>\", line 983, in _find_and_load\n",
      "  File \"<frozen importlib._bootstrap>\", line 965, in _find_and_load_unlocked\n",
      "ModuleNotFoundError: No module named 'tensorflow_core.estimator'\n"
     ]
    }
   ],
   "source": [
    "if __name__ == \"__main__\":\n",
    "    \n",
    "    # 환경 생성\n",
    "    env = Env(render_speed=0.05)\n",
    "    state_size = 15\n",
    "    action_space = [0, 1, 2, 3, 4]\n",
    "    action_size = len(action_space)\n",
    "    agent = DeepSARSAgent(state_size, action_size)\n",
    "    \n",
    "    scores, episodes = [], []\n",
    "    \n",
    "    EPISODES = 10\n",
    "    for e in range(EPISODES):\n",
    "        score = 0\n",
    "        done = False\n",
    "        state = env.reset()\n",
    "        state = np.reshape(state, [1, state_size])\n",
    "        \n",
    "        while not done:\n",
    "            action = agent.get_action(state)\n",
    "            \n",
    "            next_state, reward, done = env.step(action)\n",
    "            next_state = np.reshape(next_state, [1, state_size])\n",
    "            \n",
    "            state = next_state\n",
    "            score += reward\n",
    "            \n",
    "            if done:\n",
    "                print(\"episode: {:3d} | score: {:3d}\".format(e, score))"
   ]
  },
  {
   "cell_type": "code",
   "execution_count": null,
   "metadata": {},
   "outputs": [],
   "source": []
  },
  {
   "cell_type": "code",
   "execution_count": null,
   "metadata": {},
   "outputs": [],
   "source": []
  }
 ],
 "metadata": {
  "kernelspec": {
   "display_name": "rein_study",
   "language": "python",
   "name": "rein_study"
  },
  "language_info": {
   "codemirror_mode": {
    "name": "ipython",
    "version": 3
   },
   "file_extension": ".py",
   "mimetype": "text/x-python",
   "name": "python",
   "nbconvert_exporter": "python",
   "pygments_lexer": "ipython3",
   "version": "3.7.13"
  }
 },
 "nbformat": 4,
 "nbformat_minor": 2
}
